<?xml version="1.0" ?>
<!-- =================================================================================== -->
<!-- |    This document was autogenerated by xacro from a1.xacro                       | -->
<!-- |    EDITING THIS FILE BY HAND IS NOT RECOMMENDED                                 | -->
<!-- =================================================================================== -->
<robot name="clean_robot">
  <!-- =========================== XACRO Properties ========================= -->
  <!-- ====================================================================== -->
  <material name="black">
    <color rgba="0.0 0.0 0.0 1.0"/>
  </material>
  <material name="dark">
    <color rgba="0.3 0.3 0.3 1.0"/>
  </material>
  <material name="light_black">
    <color rgba="0.4 0.4 0.4 1.0"/>
  </material>
  <material name="blue">
    <color rgba="0.0 0.0 0.8 1.0"/>
  </material>
  <material name="green">
    <color rgba="0.0 0.8 0.0 1.0"/>
  </material>
  <material name="grey">
    <color rgba="0.5 0.5 0.5 1.0"/>
  </material>
  <material name="orange">
    <color rgba="1.0 0.4235 0.0392 1.0"/>
  </material>
  <material name="brown">
    <color rgba="0.8706 0.8118 0.7647 1.0"/>
  </material>
  <material name="red">
    <color rgba="0.8 0.0 0.0 1.0"/>
  </material>
  <material name="white">
    <color rgba="1.0 1.0 1.0 1.0"/>
  </material>
  <link name="base_link">
    <visual>
      <origin rpy="0 0 0" xyz="0 0 0.065"/>
      <geometry>
        <cylinder length="0.08" radius="0.159"/>
      </geometry>
      <material name="black"/>
    </visual>
    <collision>
      <origin rpy="0 0 0" xyz="0 0 0.065"/>
      <geometry>
        <cylinder length="0.08" radius="0.18"/>
      </geometry>
    </collision>
    <inertial>
      <mass value="6.0"/>
      <origin xyz="0 0 0"/>
      <inertia ixx="0.01" ixy="0.0" ixz="0.0" iyy="0.01" iyz="0.0" izz="0.01"/>
    </inertial>
  </link>
  <gazebo reference="base_link">
    <material>Gazebo/Grey</material>
  </gazebo>
  <link name="hull_link">
    <visual>
      <origin rpy="0 0 0" xyz="0 0 0.32"/>
      <geometry>
        <cylinder length="0.56" radius="0.13"/>
      </geometry>
      <material name="black"/>
    </visual>
    <collision>
      <origin rpy="0 0 0" xyz="0 0 0.425"/>
      <geometry>
        <cylinder length="0.64" radius="0.13"/>
      </geometry>
    </collision>
    <inertial>
      <mass value="6.0"/>
      <origin xyz="0 0 0"/>
      <inertia ixx="0.18" ixy="0.0" ixz="0.0" iyy="0.18" iyz="0.0" izz="0.05"/>
    </inertial>
  </link>
  <gazebo reference="hull_link">
    <material>Gazebo/Black</material>
  </gazebo>
  <link name="hull_base">
    <visual>
      <origin rpy="0 0 0" xyz="0 0 0"/>
      <geometry>
        <mesh filename="package://namuhx-a1/meshes/base.stl"/>
      </geometry>
      <material name="black"/>
    </visual>
  </link>
  <gazebo reference="hull_base">
    <material>Gazebo/Black</material>
  </gazebo>
  <link name="hull_grill">
    <visual>
      <origin rpy="0 0 0" xyz="0 0 0"/>
      <geometry>
        <mesh filename="package://namuhx-a1/meshes/grill.stl"/>
      </geometry>
      <material name="light_black"/>
    </visual>
  </link>
  <gazebo reference="hull_grill">
    <material>Gazebo/Grey</material>
  </gazebo>
  <link name="hull_neck">
    <visual>
      <origin rpy="0 0 0" xyz="0 0 0"/>
      <geometry>
        <mesh filename="package://namuhx-a1/meshes/neck.stl"/>
      </geometry>
      <material name="dark"/>
    </visual>
  </link>
  <gazebo reference="hull_neck">
    <material>Gazebo/DarkGrey</material>
  </gazebo>
  <link name="hull_head">
    <visual>
      <origin rpy="0 0 0" xyz="0 0 0"/>
      <geometry>
        <mesh filename="package://namuhx-a1/meshes/head.stl"/>
      </geometry>
      <material name="black"/>
    </visual>
  </link>
  <gazebo reference="hull_head">
    <material>Gazebo/Black</material>
  </gazebo>
  <link name="hull_face">
    <visual>
      <origin rpy="0 0 0" xyz="0 0 0"/>
      <geometry>
        <mesh filename="package://namuhx-a1/meshes/face.stl"/>
      </geometry>
      <material name="dark"/>
    </visual>
  </link>
  <gazebo reference="hull_face">
    <material>Gazebo/DarkGrey</material>
  </gazebo>
  <link name="wheel_main_left_link">
    <visual>
      <origin rpy="0 0 0" xyz="0 0 0"/>
      <geometry>
        <cylinder length="0.0307" radius="0.0501"/>
      </geometry>
      <material name="dark"/>
    </visual>
    <collision>
      <origin rpy="0 0 0" xyz="0 0 0"/>
      <geometry>
        <cylinder length="0.0307" radius="0.0501"/>
      </geometry>
    </collision>
    <inertial>
      <mass value="1.0"/>
      <origin xyz="0 0 0"/>
      <inertia ixx="0.01" ixy="0.0" ixz="0.0" iyy="0.01" iyz="0.0" izz="0.01"/>
    </inertial>
  </link>
  <gazebo reference="wheel_main_left_link">
    <material>Gazebo/DarkGrey</material>
  </gazebo>
  <link name="wheel_main_right_link">
    <visual>
      <origin rpy="0 0 0" xyz="0 0 0"/>
      <geometry>
        <cylinder length="0.0307" radius="0.0501"/>
      </geometry>
      <material name="dark"/>
    </visual>
    <collision>
      <origin rpy="0 0 0" xyz="0 0 0"/>
      <geometry>
        <cylinder length="0.0307" radius="0.0501"/>
      </geometry>
    </collision>
    <inertial>
      <mass value="1.0"/>
      <origin xyz="0 0 0"/>
      <inertia ixx="0.01" ixy="0.0" ixz="0.0" iyy="0.01" iyz="0.0" izz="0.01"/>
    </inertial>
  </link>
  <gazebo reference="wheel_main_right_link">
    <material>Gazebo/DarkGrey</material>
  </gazebo>
  <link name="wheel_sub_front_link">
    <visual>
      <origin rpy="0 0 0" xyz="0 0 0"/>
      <geometry>
        <sphere radius="0.0125"/>
      </geometry>
      <material name="dark"/>
    </visual>
    <collision>
      <origin rpy="0 0 0" xyz="0 0 0"/>
      <geometry>
        <sphere radius="0.0125"/>
      </geometry>
    </collision>
    <inertial>
      <mass value="0.2"/>
      <origin xyz="0 0 0"/>
      <inertia ixx="0.01" ixy="0.0" ixz="0.0" iyy="0.01" iyz="0.0" izz="0.01"/>
    </inertial>
  </link>
  <gazebo reference="wheel_sub_front_link">
    <material>Gazebo/DarkGrey</material>
  </gazebo>
  <link name="wheel_sub_front_swivel">
    <visual>
      <origin rpy="0 0 0" xyz="0 0 0.018"/>
      <geometry>
        <cylinder length="0.02" radius="0.02125"/>
      </geometry>
      <material name="dark"/>
    </visual>
    <collision>
      <origin rpy="0 0 0" xyz="0 0 0.018"/>
      <geometry>
        <cylinder length="0.02" radius="0.02125"/>
      </geometry>
    </collision>
    <inertial>
      <mass value="0.1"/>
      <origin xyz="0 0 0"/>
      <inertia ixx="0.01" ixy="0.0" ixz="0.0" iyy="0.01" iyz="0.0" izz="0.01"/>
    </inertial>
  </link>
  <gazebo reference="wheel_sub_front_swivel">
    <material>Gazebo/Grey</material>
  </gazebo>
  <link name="wheel_sub_back_link">
    <visual>
      <origin rpy="0 0 0" xyz="0 0 0"/>
      <geometry>
        <sphere radius="0.0125"/>
      </geometry>
      <material name="dark"/>
    </visual>
    <collision>
      <origin rpy="0 0 0" xyz="0 0 0"/>
      <geometry>
        <sphere radius="0.0125"/>
      </geometry>
    </collision>
    <inertial>
      <mass value="0.2"/>
      <origin xyz="0 0 0"/>
      <inertia ixx="0.01" ixy="0.0" ixz="0.0" iyy="0.01" iyz="0.0" izz="0.01"/>
    </inertial>
  </link>
  <gazebo reference="wheel_sub_back_link">
    <material>Gazebo/DarkGrey</material>
  </gazebo>
  <link name="wheel_sub_back_swivel">
    <visual>
      <origin rpy="0 0 0" xyz="0 0 0.018"/>
      <geometry>
        <cylinder length="0.02" radius="0.02125"/>
      </geometry>
      <material name="dark"/>
    </visual>
    <collision>
      <origin rpy="0 0 0" xyz="0 0 0.018"/>
      <geometry>
        <cylinder length="0.02" radius="0.02125"/>
      </geometry>
    </collision>
    <inertial>
      <mass value="0.1"/>
      <origin xyz="0 0 0"/>
      <inertia ixx="0.01" ixy="0.0" ixz="0.0" iyy="0.01" iyz="0.0" izz="0.01"/>
    </inertial>
  </link>
  <gazebo reference="wheel_sub_back_swivel">
    <material>Gazebo/Grey</material>
  </gazebo>
  <link name="imu_link"/>
  <link name="base_sensor"/>
  <link name="base_sensor_lidar_front">
    <visual>
      <origin rpy="0 0 0" xyz="0 0 0"/>
      <geometry>
        <cylinder length="0.0176" radius="0.0176"/>
      </geometry>
      <material name="red"/>
    </visual>
  </link>
  <gazebo reference="base_sensor_lidar_front">
    <material>Gazebo/Red</material>
  </gazebo>
  <link name="base_sensor_lidar_back">
    <visual>
      <origin rpy="0 0 0" xyz="0 0 0"/>
      <geometry>
        <cylinder length="0.0176" radius="0.0176"/>
      </geometry>
      <material name="red"/>
    </visual>
  </link>
  <gazebo reference="base_sensor_lidar_back">
    <material>Gazebo/Red</material>
  </gazebo>
  <link name="base_sensor_tof_left">
    <visual>
      <origin rpy="0 0 0" xyz="0 0 0"/>
      <geometry>
        <sphere radius="0.0176"/>
      </geometry>
      <material name="green"/>
    </visual>
  </link>
  <gazebo reference="base_sensor_tof_left">
    <material>Gazebo/Green</material>
  </gazebo>
  <link name="base_sensor_tof_left_frame"/>
  <link name="base_sensor_tof_right">
    <visual>
      <origin rpy="0 0 0" xyz="0 0 0"/>
      <geometry>
        <sphere radius="0.0176"/>
      </geometry>
      <material name="green"/>
    </visual>
  </link>
  <gazebo reference="base_sensor_tof_right">
    <material>Gazebo/Green</material>
  </gazebo>
  <link name="base_sensor_tof_right_frame"/>
  <link name="base_sensor_camera">
    <visual>
      <origin rpy="0 0 0" xyz="0 0 0"/>
      <geometry>
        <sphere radius="0.0176"/>
      </geometry>
      <material name="blue"/>
    </visual>
  </link>
  <gazebo reference="base_sensor_camera">
    <material>Gazebo/SkyBlue</material>
  </gazebo>
  <link name="base_sensor_camera_frame"/>
  <link name="base_sensor_ray">
    <visual>
      <origin rpy="0 0 0" xyz="0 0 0"/>
      <geometry>
        <sphere radius="0.0034"/>
      </geometry>
      <material name="orange"/>
    </visual>
  </link>
  <gazebo reference="base_sensor_ray">
    <material>Gazebo/Yellow</material>
  </gazebo>
  <!-- Joints -->
  <joint name="hull_joint" type="fixed">
    <parent link="base_link"/>
    <child link="hull_link"/>
    <origin rpy="0 0 1.570796326795" xyz="0 0 0"/>
  </joint>
  <joint name="hull_base_joint" type="fixed">
    <parent link="hull_link"/>
    <child link="hull_base"/>
    <origin rpy="0 0 0" xyz="0 0 0"/>
  </joint>
  <joint name="hull_grill_joint" type="fixed">
    <parent link="hull_link"/>
    <child link="hull_grill"/>
    <origin rpy="0 0 0" xyz="0 0 0"/>
  </joint>
  <joint name="hull_neck_joint" type="fixed">
    <parent link="hull_link"/>
    <child link="hull_neck"/>
    <origin rpy="0 0 0" xyz="0 0 0"/>
  </joint>
  <joint name="hull_head_joint" type="fixed">
    <parent link="hull_link"/>
    <child link="hull_head"/>
    <origin rpy="0 0 0" xyz="0 0 0"/>
  </joint>
  <joint name="hull_face_joint" type="fixed">
    <parent link="hull_link"/>
    <child link="hull_face"/>
    <origin rpy="0 0 0" xyz="0 0 0"/>
  </joint>
  <joint name="wheel_main_left_joint" type="continuous">
    <parent link="base_link"/>
    <child link="wheel_main_left_link"/>
    <origin rpy="-1.570796326795 0 0" xyz="0 0.1069 0.0501"/>
    <axis xyz="0 0 1"/>
  </joint>
  <joint name="wheel_main_right_joint" type="continuous">
    <parent link="base_link"/>
    <child link="wheel_main_right_link"/>
    <origin rpy="-1.570796326795 0 0" xyz="0 -0.1069 0.0501"/>
    <axis xyz="0 0 1"/>
  </joint>
  <joint name="wheel_sub_front_swivel_joint" type="continuous">
    <parent link="base_link"/>
    <child link="wheel_sub_front_swivel"/>
    <origin rpy="0 0 0" xyz="0.1166 0 0.0125"/>
    <axis xyz="0 0 1"/>
  </joint>
  <joint name="wheel_sub_front_joint" type="continuous">
    <parent link="wheel_sub_front_swivel"/>
    <child link="wheel_sub_front_link"/>
    <origin rpy="0 0 0" xyz="0.00625 0 0"/>
    <axis xyz="0 1 0"/>
  </joint>
  <joint name="wheel_sub_back_swivel_joint" type="continuous">
    <parent link="base_link"/>
    <child link="wheel_sub_back_swivel"/>
    <origin rpy="0 0 0" xyz="-0.1166 0 0.0125"/>
    <axis xyz="0 0 1"/>
  </joint>
  <joint name="wheel_sub_back_joint" type="continuous">
    <parent link="wheel_sub_back_swivel"/>
    <child link="wheel_sub_back_link"/>
    <origin rpy="0 0 0" xyz="0.00625 0 0"/>
    <axis xyz="0 1 0"/>
  </joint>
  <joint name="imu_joint" type="fixed">
    <parent link="base_link"/>
    <child link="imu_link"/>
    <origin rpy="0 0 0" xyz="0 0 0.09"/>
  </joint>
  <joint name="base_sensor_joint" type="fixed">
    <parent link="hull_link"/>
    <child link="base_sensor"/>
    <origin rpy="0 0 -1.570796326795" xyz="0 0 0.03"/>
  </joint>
  <joint name="sensor_lidar_front_joint" type="fixed">
    <parent link="base_sensor"/>
    <child link="base_sensor_lidar_front"/>
    <origin rpy="0 0 0" xyz="0.1475 0 0.0984"/>
  </joint>
  <joint name="sensor_lidar_back_joint" type="fixed">
    <parent link="base_sensor"/>
    <child link="base_sensor_lidar_back"/>
    <origin rpy="0 0 3.14159265359" xyz="-0.1475 0 0.0984"/>
  </joint>
  <joint name="sensor_tof_left_joint" type="fixed">
    <parent link="base_sensor"/>
    <child link="base_sensor_tof_left"/>
    <origin rpy="0 0.0 0.2792526803191111" xyz="0.145 0.075 0.052"/>
  </joint>
  <joint name="sensor_tof_left_frame_joint" type="fixed">
    <parent link="base_sensor_tof_left"/>
    <child link="base_sensor_tof_left_frame"/>
    <origin rpy="-1.570796326795 0 -1.570796326795" xyz="0 0 0"/>
  </joint>
  <joint name="sensor_tof_right_joint" type="fixed">
    <parent link="base_sensor"/>
    <child link="base_sensor_tof_right"/>
    <origin rpy="0 0.0 -0.2792526803191111" xyz="0.145 -0.075 0.052"/>
  </joint>
  <joint name="sensor_tof_right_frame_joint" type="fixed">
    <parent link="base_sensor_tof_right"/>
    <child link="base_sensor_tof_right_frame"/>
    <origin rpy="-1.570796326795 0 -1.570796326795" xyz="0 0 0"/>
  </joint>
  <joint name="sensor_camera_joint" type="fixed">
    <parent link="base_sensor"/>
    <child link="base_sensor_camera"/>
    <origin rpy="0 0.43633231299861114 0" xyz="0.145 0 0.561"/>
  </joint>
  <joint name="sensor_camera_frame_joint" type="fixed">
    <parent link="base_sensor_camera"/>
    <child link="base_sensor_camera_frame"/>
    <origin rpy="-1.570796326795 0 -1.570796326795" xyz="0 0 0"/>
  </joint>
  <joint name="sensor_ray_joint" type="fixed">
    <parent link="base_sensor"/>
    <child link="base_sensor_ray"/>
    <origin rpy="0 -0.26179938779916667 0" xyz="0.144 0 0.6095"/>
  </joint>
  <!-- Plugins -->
  <gazebo>
    <plugin filename="libgazebo_ros_diff_drive.so" name="diff_drive_controller">
      <left_joint>wheel_main_left_joint</left_joint>
      <right_joint>wheel_main_right_joint</right_joint>
      <wheel_separation>0.2138</wheel_separation>
      <wheel_diameter>0.1002</wheel_diameter>
      <command_topic>cmd_vel</command_topic>
      <odometry_topic>odom</odometry_topic>
      <robot_base_frame>base_link</robot_base_frame>
      <publish_odom>true</publish_odom>
      <publish_odom_tf>true</publish_odom_tf>
    </plugin>
  </gazebo>
  <gazebo reference="base_sensor_lidar_front">
    <sensor name="base_sensor_lidar_front_sensor" type="ray">
      <update_rate>10</update_rate>
      <ray>
        <scan>
          <horizontal>
            <samples>241</samples>
            <resolution>1</resolution>
            <min_angle>-1.8995</min_angle>
            <max_angle>1.8995</max_angle>
          </horizontal>
        </scan>
        <range>
          <min>0.05</min>
          <max>8</max>
          <resolution>0.001</resolution>
        </range>
        <noise>
          <type>gaussian</type>
          <mean>0.0</mean>
          <stddev>0</stddev>
        </noise>
      </ray>
      <plugin filename="libgazebo_ros_ray_sensor.so" name="base_sensor_lidar_front_controller">
        <output_type>sensor_msgs/LaserScan</output_type>
        <frame_name>base_sensor_lidar_front</frame_name>
      </plugin>
    </sensor>
  </gazebo>
  <gazebo reference="base_sensor_lidar_back">
    <sensor name="base_sensor_lidar_back_sensor" type="ray">
      <update_rate>10</update_rate>
      <ray>
        <scan>
          <horizontal>
            <samples>241</samples>
            <resolution>1</resolution>
            <min_angle>-1.8995</min_angle>
            <max_angle>1.8995</max_angle>
          </horizontal>
        </scan>
        <range>
          <min>0.05</min>
          <max>8</max>
          <resolution>0.001</resolution>
        </range>
        <noise>
          <type>gaussian</type>
          <mean>0.0</mean>
          <stddev>0</stddev>
        </noise>
      </ray>
      <plugin filename="libgazebo_ros_ray_sensor.so" name="base_sensor_lidar_back_controller">
        <output_type>sensor_msgs/LaserScan</output_type>
        <frame_name>base_sensor_lidar_back</frame_name>
      </plugin>
    </sensor>
  </gazebo>
  <gazebo reference="base_sensor_tof_left">
    <sensor name="base_sensor_tof_left_sensor" type="depth">
      <update_rate>10</update_rate>
      <camera>
        <horizontal_fov>0.6108652381980556</horizontal_fov>
        <image>
          <width>8</width>
          <height>8</height>
          <format>R8G8B8</format>
        </image>
        <clip>
          <near>0.05</near>
          <far>4</far>
        </clip>
        <noise>
          <type>gaussian</type>
          <mean>0</mean>
          <stddev>0</stddev>
        </noise>
      </camera>
      <plugin filename="libgazebo_ros_camera.so" name="base_sensor_tof_left_controller">
        <frame_name>base_sensor_tof_left_frame</frame_name>
        <min_depth>0.05</min_depth>
        <max_depth>4</max_depth>
      </plugin>
    </sensor>
  </gazebo>
  <gazebo reference="base_sensor_tof_right">
    <sensor name="base_sensor_tof_right_sensor" type="depth">
      <update_rate>10</update_rate>
      <camera>
        <horizontal_fov>0.6108652381980556</horizontal_fov>
        <image>
          <width>8</width>
          <height>8</height>
          <format>R8G8B8</format>
        </image>
        <clip>
          <near>0.05</near>
          <far>4</far>
        </clip>
        <noise>
          <type>gaussian</type>
          <mean>0</mean>
          <stddev>0</stddev>
        </noise>
      </camera>
      <plugin filename="libgazebo_ros_camera.so" name="base_sensor_tof_right_controller">
        <frame_name>base_sensor_tof_right_frame</frame_name>
        <min_depth>0.05</min_depth>
        <max_depth>4</max_depth>
      </plugin>
    </sensor>
  </gazebo>
  <gazebo reference="base_sensor_camera">
    <sensor name="base_sensor_camera_sensor" type="camera">
      <update_rate>10</update_rate>
      <camera>
        <horizontal_fov>2.0245819323135557</horizontal_fov>
        <image>
          <width>640</width>
          <height>480</height>
          <format>R8G8B8</format>
        </image>
        <clip>
          <near>0.05</near>
          <far>40</far>
        </clip>
      </camera>
      <plugin filename="libgazebo_ros_camera.so" name="base_sensor_camera_controller">
        <frame_name>base_sensor_camera_frame</frame_name>
      </plugin>
    </sensor>
  </gazebo>
  <gazebo reference="base_sensor_ray">
    <sensor name="base_sensor_ray_sensor" type="ray">
      <update_rate>10</update_rate>
      <ray>
        <scan>
          <horizontal>
            <samples>3</samples>
            <resolution>1</resolution>
            <min_angle>-0.005</min_angle>
            <max_angle>0.005</max_angle>
          </horizontal>
        </scan>
        <range>
          <min>0.01</min>
          <max>1</max>
          <resolution>0.001</resolution>
        </range>
        <noise>
          <type>gaussian</type>
          <mean>0.0</mean>
          <stddev>0</stddev>
        </noise>
      </ray>
      <plugin filename="libgazebo_ros_ray_sensor.so" name="base_sensor_ray_controller">
        <output_type>sensor_msgs/LaserScan</output_type>
        <frame_name>base_sensor_ray</frame_name>
      </plugin>
    </sensor>
  </gazebo>
  <link name="collision_ray_0"/>
  <joint name="collision_ray_0_joint" type="fixed">
    <parent link="base_link"/>
    <child link="collision_ray_0"/>
    <origin rpy="0 0 0" xyz="0 0 0.03"/>
  </joint>
  <gazebo reference="collision_ray_0">
    <sensor name="collision_ray_0_sensor" type="ray">
      <update_rate>10</update_rate>
      <ray>
        <scan>
          <horizontal>
            <samples>32</samples>
            <resolution>1</resolution>
            <min_angle>-3.14</min_angle>
            <max_angle>3.14</max_angle>
          </horizontal>
        </scan>
        <range>
          <min>0.2</min>
          <max>0.3</max>
          <resolution>0.001</resolution>
        </range>
        <noise>
          <type>gaussian</type>
          <mean>0.0</mean>
          <stddev>0</stddev>
        </noise>
      </ray>
      <plugin filename="libgazebo_ros_ray_sensor.so" name="collision_ray_0_controller">
        <output_type>sensor_msgs/LaserScan</output_type>
        <frame_name>collision_ray_0</frame_name>
      </plugin>
    </sensor>
  </gazebo>
  <link name="collision_ray_1"/>
  <joint name="collision_ray_1_joint" type="fixed">
    <parent link="base_link"/>
    <child link="collision_ray_1"/>
    <origin rpy="0 0 0" xyz="0 0 0.25"/>
  </joint>
  <gazebo reference="collision_ray_1">
    <sensor name="collision_ray_1_sensor" type="ray">
      <update_rate>10</update_rate>
      <ray>
        <scan>
          <horizontal>
            <samples>32</samples>
            <resolution>1</resolution>
            <min_angle>-3.14</min_angle>
            <max_angle>3.14</max_angle>
          </horizontal>
        </scan>
        <range>
          <min>0.2</min>
          <max>0.3</max>
          <resolution>0.001</resolution>
        </range>
        <noise>
          <type>gaussian</type>
          <mean>0.0</mean>
          <stddev>0</stddev>
        </noise>
      </ray>
      <plugin filename="libgazebo_ros_ray_sensor.so" name="collision_ray_1_controller">
        <output_type>sensor_msgs/LaserScan</output_type>
        <frame_name>collision_ray_1</frame_name>
      </plugin>
    </sensor>
  </gazebo>
  <link name="collision_ray_2"/>
  <joint name="collision_ray_2_joint" type="fixed">
    <parent link="base_link"/>
    <child link="collision_ray_2"/>
    <origin rpy="0 0 0" xyz="0 0 0.5"/>
  </joint>
  <gazebo reference="collision_ray_2">
    <sensor name="collision_ray_2_sensor" type="ray">
      <update_rate>10</update_rate>
      <ray>
        <scan>
          <horizontal>
            <samples>32</samples>
            <resolution>1</resolution>
            <min_angle>-3.14</min_angle>
            <max_angle>3.14</max_angle>
          </horizontal>
        </scan>
        <range>
          <min>0.2</min>
          <max>0.3</max>
          <resolution>0.001</resolution>
        </range>
        <noise>
          <type>gaussian</type>
          <mean>0.0</mean>
          <stddev>0</stddev>
        </noise>
      </ray>
      <plugin filename="libgazebo_ros_ray_sensor.so" name="collision_ray_2_controller">
        <output_type>sensor_msgs/LaserScan</output_type>
        <frame_name>collision_ray_2</frame_name>
      </plugin>
    </sensor>
  </gazebo>
  <link name="collision_ray_3"/>
  <joint name="collision_ray_3_joint" type="fixed">
    <parent link="base_link"/>
    <child link="collision_ray_3"/>
    <origin rpy="0 0 0" xyz="0 0 0.75"/>
  </joint>
  <gazebo reference="collision_ray_3">
    <sensor name="collision_ray_3_sensor" type="ray">
      <update_rate>10</update_rate>
      <ray>
        <scan>
          <horizontal>
            <samples>32</samples>
            <resolution>1</resolution>
            <min_angle>-3.14</min_angle>
            <max_angle>3.14</max_angle>
          </horizontal>
        </scan>
        <range>
          <min>0.2</min>
          <max>0.3</max>
          <resolution>0.001</resolution>
        </range>
        <noise>
          <type>gaussian</type>
          <mean>0.0</mean>
          <stddev>0</stddev>
        </noise>
      </ray>
      <plugin filename="libgazebo_ros_ray_sensor.so" name="collision_ray_3_controller">
        <output_type>sensor_msgs/LaserScan</output_type>
        <frame_name>collision_ray_3</frame_name>
      </plugin>
    </sensor>
  </gazebo>
</robot>
